Workbook

Sheet Pricing Calculator
A1: Photon Brothers — OpenSolar Pricing Calculator
A3: SYSTEM INPUTS
A4: System Size (kW) | B4: 10 | C4: ← Enter system size
A5: Number of Panels | B5: 23
A6: Number of Stories | B6: 1 | C6: ← 1, 2, or 3
A7: Roof Pitch (degrees) | B7: 20
A8: Roof Type | B8: Comp/Asphalt | C8: ← Comp/Asphalt, Flat Concrete, Tile Clay, Tar/Gravel, Membrane EPDM
A9: Pricing Scheme | B9: Base | C9: ← Base, Ventura, Bay Area, D&R, Off Grid Homes
A10: Markup % (auto from scheme) | B10: =VLOOKUP(B9,'Pricing Schemes'!A2:B6,2,FALSE()) -> 0.4
A12: EQUIPMENT SELECTION
A13: Component | B13: Selection | C13: Unit Cost | D13: Qty | E13: Total Cost
A14: Module | B14: SEG-440-BTD-BG | C14: =IFERROR(VLOOKUP(B14,'Equipment Library'!A3:C9,3,FALSE()),0) -> 305 | D14: =B5 -> 23 | E14: =C14*D14 -> 7015
A15: Inverter | B15: IQ8MC-72-M-US [240V] | C15: =IFERROR(VLOOKUP(B15,'Equipment Library'!A13:C29,3,FALSE()),0) -> 160 | D15: 23 | E15: =C15*D15 -> 3680
A16: Battery | B16: Tesla Powerwall 3 | C16: =IFERROR(VLOOKUP(B16,'Equipment Library'!A33:E35,3,FALSE()),0) -> 7700 | D16: 1 | E16: =C16*D16 -> 7700
A17: Battery Labor Adj (per unit) | C17: =IFERROR(VLOOKUP(B16,'Equipment Library'!A33:F35,6,FALSE()),0) -> 2600 | D17: =D16 -> 1 | E17: =C17*D17 -> 2600
A18: Other Components (total) | C18: 1800 | D18: ← e.g. Gateway | E18: =C18 -> 1800
A19: SUBTOTAL: Component Costs | E19: =SUM(E14:E18) -> 22795
A21: COST SCHEME OVERHEAD (Costing Scheme Itemized)
A22: Line Item | B22: Rate | C22: Basis | D22: Watts | E22: Cost
A23: Racking | B23: 0.15 | C23: /W | D23: =B4*1000 -> 10000 | E23: =B23*D23 -> 1500
A24: BOS | B24: 0.15 | C24: /W | D24: =B4*1000 -> 10000 | E24: =B24*D24 -> 1500
A25: Labor | B25: 0.55 | C25: /W | D25: =B4*1000 -> 10000 | E25: =B25*D25 -> 5500
A26: Lead Gen (flat) | B26: 300 | C26: /system | E26: =B26 -> 300
A27: Lead Gen (variable) | B27: 0.1 | C27: /W | D27: =B4*1000 -> 10000 | E27: =B27*D27 -> 1000
A28: Salary Allocation | B28: 100 | C28: /system | E28: =B28 -> 100
A29: Pre-sale Software/Design | B29: 0.01 | C29: /W | D29: =B4*1000 -> 10000 | E29: =B29*D29 -> 100
A30: Project Management | B30: 1000 | C30: /system | E30: =B30 -> 1000
A31: Design Drawings | B31: 350 | C31: /system | E31: =B31 -> 350
A32: Permit Costs | B32: 500 | C32: /system | E32: =B32 -> 500
A33: Commission (5% of COGS+Labor) | B33: 0.05 | C33: % of COGS+Labor | E33: =B33*(E19+E23+E24+E25) -> 1564.75
A34: SUBTOTAL: Overhead | E34: =SUM(E23:E33) -> 13414.75
A36: JOB DIFFICULTY ADDERS
A37: Condition | B37: Rate (/W) | C37: Applies? | D37: Watts | E37: Cost
A38: Two Stories ($0.05/W) | B38: 0.05 | C38: =IF(B6=2,"YES","NO") -> NO | D38: =B4*1000 -> 10000 | E38: =IF(C38="YES",B38*D38,0) -> 0
A39: Three+ Stories ($0.83/W) | B39: 0.83 | C39: =IF(B6>=3,"YES","NO") -> NO | D39: =B4*1000 -> 10000 | E39: =IF(C39="YES",B39*D39,0) -> 0
A40: Steep Pitch 34°+ ($0.35/W) | B40: 0.35 | C40: =IF(AND(B7>=34,B7<44),"YES","NO") -> NO | D40: =B4*1000 -> 10000 | E40: =IF(C40="YES",B40*D40,0) -> 0
A41: Very Steep Pitch 44°+ ($0.50/W) | B41: 0.5 | C41: =IF(B7>=44,"YES","NO") -> NO | D41: =B4*1000 -> 10000 | E41: =IF(C41="YES",B41*D41,0) -> 0
A42: Tilt Rack ($0.35/W) | B42: 0.35 | C42: NO | D42: =B4*1000 -> 10000 | E42: =IF(C42="YES",B42*D42,0) -> 0
A43: Steep Rack 25°+ ($0.10/W) | B43: 0.1 | C43: NO | D43: =B4*1000 -> 10000 | E43: =IF(C43="YES",B43*D43,0) -> 0
A44: SUBTOTAL: Difficulty Adders | E44: =SUM(E38:E43) -> 0
...

Sheet Equipment Library
A1: MODULES
A2: Code | B2: Manufacturer | C2: Cost
A3: SEG-420-BTD-BG | B3: SEG Solar | C3: 0
A4: SIL-400 HC+ | B4: Silfab | C4: 200
A5: SIL-410 HC+ | B5: Silfab | C5: 205
A6: REC360TP4 Black | B6: REC Solar | C6: 150
A7: SEG-430-BTD-BG | B7: SEG Solar | C7: 300
A8: SEG-440-BTD-BG | B8: SEG Solar | C8: 305
A9: HiN-T440NF(BK) | B9: Hyundai | C9: 305
A11: INVERTERS
A12: Code | B12: Manufacturer | C12: Cost
A13: IQ8A-72-2-US | B13: Enphase | C13: 143
A14: IQ8P-72-2-INT | B14: Enphase | C14: 143
A15: IQ8X-80-M-US [240V] | B15: Enphase | C15: 158
A16: IQ8MC-72-M-US [240V] | B16: Enphase | C16: 160
A17: SE5000H-US [240V] | B17: SolarEdge | C17: 2250
A18: SE6000H-US [240V] | B18: SolarEdge | C18: 2300
A19: SE7600H-US [240V] | B19: SolarEdge | C19: 2750
A20: SE10000H-US [240V] | B20: SolarEdge | C20: 3200
A21: SE11400H-US [240V] | B21: SolarEdge | C21: 3150
A22: Tesla 3.8 kW Inverter | B22: Tesla | C22: 1200
A23: Tesla 5.0 kW Inverter | B23: Tesla | C23: 1200
A24: Tesla 7.6kW Inverter | B24: Tesla | C24: 1200
... A29: 60K-3P-480V-N | B29: Sol-Ark | C29: 17000
A31: BATTERIES
A32: Code | B32: Manufacturer | C32: Tier 1 Cost | D32: kWh | E32: Tier 2+ Cost | F32: Labor Adj
A33: Tesla Powerwall 3 | B33: Tesla | C33: 7700 | D33: 13.5 | E33: 7500 | F33: 2600
A34: Tesla PW3 Expansion Pack | B34: Tesla | C34: 5200 | D34: 13.5 | E34: 4900 | F34: 1900
A35: Enphase IQ Battery 10 | B35: Enphase | C35: 7800 | D35: 10 | E35: 7500 | F35: 3000
A37: ACCESSORIES
A38: Code | B38: Manufacturer | C38: Cost | D38: Notes
A39: Gen 3 Wall Connector | B39: Tesla | C39: 600 | D39: EV Charger
A40: Tesla Backup Switch | B40: Tesla | C40: 0 | D40: $0 cost — bundled with PW3

Sheet Pricing Schemes
A1: Scheme | B1: Markup % | C1: Auto-Apply | D1: Description
A2: Base | B2: 0.4 | C2: Yes | D2: Standard CO pricing
A3: Ventura | B3: 0.36 | C3: No | D3: Ventura County, CA
A4: Bay Area | B4: 0.5 | C4: No | D4: Bay Area, CA
A5: D&R | B5: 0.3 | C5: No | D5: De-rate & re-roof
A6: Off Grid Homes | B6: 0.65 | C6: No | D6: Off-grid systems

Sheet Cost Scheme Detail
A1: Costing Scheme Itemized — Full Rate Card
A3: COGS
B4: Rate | C4: Basis
A5: Racking | B5: $0.15 | C5: /W
A6: BOS | B6: $0.15 | C6: /W
A7: Labor | B7: $0.55 | C7: /W
A8: Lead Gen | B8: $300 + $0.10/W | C8: /system + /W
A9: Salary Allocation | B9: $100 | C9: /system
A10: Pre-sale Software/Design | B10: $0.01 | C10: /W
A11: Commission | B11: 5% | C11: of COGS + Labor
A12: Project Management | B12: $1,000 | C12: /system
A13: Design Drawings | B13: $350 | C13: /system
A14: Permit Costs | B14: $500 | C14: /system
A16: JOB DIFFICULTY
A17: Two Stories | B17: $0.05 | C17: /W
A18: Three+ Stories | B18: $0.83 | C18: /W
A19: Steep Pitch (34°+) | B19: $0.35 | C19: /W
A20: Very Steep Pitch (44°+) | B20: $0.50 | C20: /W
A21: Tilt Rack | B21: $0.35 | C21: /W
A22: Steep Rack (25°+) | B22: $0.10 | C22: /W
A24: ROOF TYPE ADDERS
A25: Comp/Asphalt Shingle | B25: $0 | C25: —
A26: Flat Concrete | B26: $0.35 | C26: /W
A27: Tile Clay | B27: $3,500 + $0.80/W | C27: /system + /W
A28: Tar & Gravel / Bitumen | B28: $0.35 | C28: /W
A29: Membrane EPDM | B29: $0.35 | C29: /W
A31: SLOPE THRESHOLDS
A32: Steep Pitch starts at | B32: 34°
A33: Very Steep Pitch starts at | B33: 44°
A34: Moderate Rack Slope | B34: 10°
A35: Steep Rack Slope | B35: 25°
A36: Very Steep Rack Slope | B36: 30°
