Workbook

Sheet Costs & Prices
A1: MODULES
A2: Name | B2: Cost | C2: Watts | D2: DC Qual?
A3: Hyundai 440W (Black) | B3: 305 | C3: 440 | D3: No
A4: Silfab 440W (Black/Gold) | B4: 305 | C4: 440 | D4: No
A5: Silfab 430W (Black/Gold) | B5: 300 | C5: 430 | D5: No
A7: INVERTERS
A8: Name | B8: Cost
A9: Tesla 7.6kW Inverter | B9: 1200
A10: Tesla 5.0kW Inverter | B10: 1200
A11: Tesla 3.8kW Inverter | B11: 1200
A12: Enphase IQ8MC Micro | B12: 160
A13: Enphase IQ8X Micro | B13: 158
A14: Enphase IQ8A Micro | B14: 143
A15: Enphase IQ8M Micro | B15: 150
A17: BATTERIES
A18: Name | B18: Cost | C18: Labour | D18: DC Qual?
A19: Tesla Powerwall 3 | B19: 7700 | C19: 2600 | D19: Yes
A20: PW3 Expansion Pack | B20: 5000 | C20: 1900 | D20: Yes
A22: OTHER EQUIPMENT
A23: Name | B23: Cost | C23: Bundled?
A24: Tesla Wall Connector (Gen 3) | B24: 600 | C24: No
A25: Tesla Backup Switch | B25: 305 | C25: Yes
A27: PRICING SCHEMES
A28: Scheme | B28: Markup %
A29: Base (Colorado) | B29: 0.4
A30: Ventura | B30: 0.36
A31: Bay Area | B31: 0.5
A32: D&R | B32: 0.3
A33: Off Grid Homes | B33: 0.65
A35: ROOF TYPES
A36: Type | B36: Fixed ($) | C36: Per-Watt ($)
A37: Comp/Asphalt Shingle | B37: 0 | C37: 0
A38: Flat Membrane | B38: 0 | C38: 0.35
A39: Tile Concrete | B39: 3500 | C39: 0.8
A40: Wood Shake | B40: 0 | C40: 0.35
A41: Metal Corrugated | B41: 0 | C41: 0.35
A43: STOREY ADDERS
A44: Stories | B44: Per-Watt ($)
A45: 1 Story | B45: 0
A46: 2 Stories | B46: 0.05
...

Sheet Calculator
A1: PB Pricing Calculator
A3: EQUIPMENT
B4: Selection | C4: Qty | D4: Cost/Unit | E4: Total
A5: Module | B5: Hyundai 440W (Black) | C5: 0 | D5: =VLOOKUP(B5,'Costs & Prices'!A3:B5,2,FALSE()) -> 305 | E5: =C5*D5 -> 0 | F5: =VLOOKUP(B5,'Costs & Prices'!A3:C5,3,FALSE()) -> 440
A6: Module 2 (optional) | B6: (none) | C6: 0 | D6: =IF(B6="(none)",0,VLOOKUP(B6,'Costs & Prices'!A3:B5,2,FALSE())) -> 0 | E6: =C6*D6 -> 0 | F6: =IF(B6="(none)",0,VLOOKUP(B6,'Costs & Prices'!A3:C5,3,FALSE())) -> 0
A7: Inverter | B7: Tesla 7.6kW Inverter | C7: 0 | D7: =VLOOKUP(B7,'Costs & Prices'!A9:B15,2,FALSE()) -> 1200 | E7: =C7*D7 -> 0
A8: Inverter 2 (optional) | B8: (none) | C8: 0 | D8: =IF(B8="(none)",0,VLOOKUP(B8,'Costs & Prices'!A9:B15,2,FALSE())) -> 0 | E8: =C8*D8 -> 0
A9: Battery | B9: (none) | C9: 0 | D9: =IF(B9="(none)",0,VLOOKUP(B9,'Costs & Prices'!A19:B20,2,FALSE())) -> 0 | E9: =C9*D9 -> 0 | F9: =IF(B9="(none)",0,VLOOKUP(B9,'Costs & Prices'!A19:C20,3,FALSE())) -> 0
A10: Battery 2 (optional) | B10: (none) | C10: 0 | D10: =IF(B10="(none)",0,VLOOKUP(B10,'Costs & Prices'!A19:B20,2,FALSE())) -> 0 | E10: =C10*D10 -> 0 | F10: =IF(B10="(none)",0,VLOOKUP(B10,'Costs & Prices'!A19:C20,3,FALSE())) -> 0
A11: EV Charger | B11: No | C11: 1 | D11: ='Costs & Prices'!B24 -> 600 | E11: =IF(B11="Yes",C11*D11,0) -> 0
A13: CONFIGURATION
A14: Pricing Scheme | B14: Base (Colorado) | C14: Markup: | D14: =VLOOKUP(B14,'Costs & Prices'!A29:B33,2,FALSE()) -> 0.4
A15: Roof Type | B15: Comp/Asphalt Shingle | C15: Fixed: | D15: =VLOOKUP(B15,'Costs & Prices'!A37:C41,2,FALSE()) -> 0 | E15: =VLOOKUP(B15,'Costs & Prices'!A37:C41,3,FALSE()) -> 0
A16: Storey | B16: 1 Story | C16: $/W: | D16: =VLOOKUP(B16,'Costs & Prices'!A45:B47,2,FALSE()) -> 0
A17: Roof Pitch | B17: Standard (< 34°) | C17: $/W: | D17: =VLOOKUP(B17,'Costs & Prices'!A51:B53,2,FALSE()) -> 0
A18: PE Deal? | B18: No
A19: Energy Community? | B19: No
A20: Custom Adder ($) | B20: 0 | C20: e.g. -1000 promo
A22: SYSTEM SUMMARY
A23: Total Panels | B23: =C5+C6 -> 0
A24: Total Watts | B24: =C5*F5+C6*F6 -> 0 | C24: =B24/1000 -> 0 | D24: kW DC
A25: Total Batteries | B25: =C9+C10 -> 0
A26: Battery Only? | B26: =IF(AND(B23=0,B25>0),"Yes","No") -> No
A28: COST BREAKDOWN
A29: Module Cost | E29: =E5+E6 -> 0
A30: Inverter Cost | E30: =E7+E8 -> 0
A31: Battery Cost | E31: =E9+E10 -> 0
A32: Other Equipment | E32: =E11 -> 0
A33: Battery Misc | E33: =IF(OR(B26="Yes",B25>=2),IF(B25>0,'Costs & Prices'!B68,0),0) -> 0
A34: Racking | E34: =B24*'Costs & Prices'!B57 -> 0
A35: BOS | E35: =B24*'Costs & Prices'!B58 -> 0
A36: COGS | E36: =SUM(E29:E35) -> 0
A38: Roof Adder | E38: =D15+B24*E15 -> 0
A39: Storey Adder | E39: =B24*D16 -> 0
A40: Pitch Adder | E40: =B24*D17 -> 0
A41: Extra Costs | E41: =SUM(E38:E40) -> 0
A43: General Labour | E43: =B24*'Costs & Prices'!B59 -> 0
A44: Battery Labour | E44: =C9*F9+C10*F10 -> 0
A45: Total Labour | E45: =SUM(E43:E44) -> 0
A47: Lead Gen | E47: ='Costs & Prices'!B60+B24*'Costs & Prices'!B61 -> 300
...
